Traceback (most recent call last):
  File "/Users/tom/opt/anaconda3/envs/book/lib/python3.8/site-packages/jupyter_cache/executors/utils.py", line 51, in single_nb_execution
    executenb(
  File "/Users/tom/opt/anaconda3/envs/book/lib/python3.8/site-packages/nbclient/client.py", line 1112, in execute
    return NotebookClient(nb=nb, resources=resources, km=km, **kwargs).execute()
  File "/Users/tom/opt/anaconda3/envs/book/lib/python3.8/site-packages/nbclient/util.py", line 74, in wrapped
    return just_run(coro(*args, **kwargs))
  File "/Users/tom/opt/anaconda3/envs/book/lib/python3.8/site-packages/nbclient/util.py", line 53, in just_run
    return loop.run_until_complete(coro)
  File "/Users/tom/opt/anaconda3/envs/book/lib/python3.8/asyncio/base_events.py", line 616, in run_until_complete
    return future.result()
  File "/Users/tom/opt/anaconda3/envs/book/lib/python3.8/site-packages/nbclient/client.py", line 553, in async_execute
    await self.async_execute_cell(
  File "/Users/tom/opt/anaconda3/envs/book/lib/python3.8/site-packages/nbclient/client.py", line 857, in async_execute_cell
    self._check_raise_for_error(cell, exec_reply)
  File "/Users/tom/opt/anaconda3/envs/book/lib/python3.8/site-packages/nbclient/client.py", line 760, in _check_raise_for_error
    raise CellExecutionError.from_cell_and_msg(cell, exec_reply_content)
nbclient.exceptions.CellExecutionError: An error occurred while executing the following cell:
------------------
import numpy as np
import matplotlib.pyplot as plt
import matplotlib.image as mpimg

from fooof.plts.spectra import plot_spectrum_shading
from fooof.utils import trim_spectrum

from neurodsp.sim import sim_oscillation, sim_powerlaw, sim_combined
from neurodsp.filt import filter_signal
from neurodsp.spectral import compute_spectrum
from neurodsp.timefrequency import amp_by_time, phase_by_time, freq_by_time
from neurodsp.utils import create_times, set_random_seed
from neurodsp.plts.time_series import plot_time_series, plot_instantaneous_measure
------------------

[0;31m---------------------------------------------------------------------------[0m
[0;31mModuleNotFoundError[0m                       Traceback (most recent call last)
[0;32m<ipython-input-1-8454eee7db9a>[0m in [0;36m<module>[0;34m[0m
[1;32m      3[0m [0;32mimport[0m [0mmatplotlib[0m[0;34m.[0m[0mimage[0m [0;32mas[0m [0mmpimg[0m[0;34m[0m[0;34m[0m[0m
[1;32m      4[0m [0;34m[0m[0m
[0;32m----> 5[0;31m [0;32mfrom[0m [0mfooof[0m[0;34m.[0m[0mplts[0m[0;34m.[0m[0mspectra[0m [0;32mimport[0m [0mplot_spectrum_shading[0m[0;34m[0m[0;34m[0m[0m
[0m[1;32m      6[0m [0;32mfrom[0m [0mfooof[0m[0;34m.[0m[0mutils[0m [0;32mimport[0m [0mtrim_spectrum[0m[0;34m[0m[0;34m[0m[0m
[1;32m      7[0m [0;34m[0m[0m

[0;31mModuleNotFoundError[0m: No module named 'fooof'
ModuleNotFoundError: No module named 'fooof'

